<?xml version="1.0" encoding="utf-8"?>
<!-- This URDF was automatically created by SolidWorks to URDF Exporter! Originally created by Stephen Brawner (brawner@gmail.com) 
     Commit Version: 1.6.0-1-g15f4949  Build Version: 1.6.7594.29634
     For more information, please see http://wiki.ros.org/sw_urdf_exporter -->
<robot
  name="medibot4">
  <link
    name="base_link">
    <inertial>
      <origin
        xyz="-0.007005 0.5622 0.057324"
        rpy="0 0 0" />
      <mass
        value="16.587" />
      <inertia
        ixx="0.33575"
        ixy="-0.0016631"
        ixz="0.00045583"
        iyy="0.26398"
        iyz="0.0005298"
        izz="0.47721" />
    </inertial>
    <visual>
      <origin
        xyz="0 0 0"
        rpy="0 0 0" />
      <geometry>
        <mesh
          filename="package://medibot4/meshes/base_link.STL" />
      </geometry>
      <material
        name="">
        <color
          rgba="0.79216 0.81961 0.93333 1" />
      </material>
    </visual>
    <collision>
      <origin
        xyz="0 0 0"
        rpy="0 0 0" />
      <geometry>
        <mesh
          filename="package://medibot4/meshes/base_link.STL" />
      </geometry>
    </collision>
  </link>
  <link
    name="right_wheel">
    <inertial>
      <origin
        xyz="2.7756E-17 0 -0.1"
        rpy="0 0 0" />
      <mass
        value="18.237" />
      <inertia
        ixx="0.20771"
        ixy="8.4374E-34"
        ixz="-6.6177E-18"
        iyy="0.20771"
        iyz="3.0434E-34"
        izz="0.29384" />
    </inertial>
    <visual>
      <origin
        xyz="0 0 0"
        rpy="0 0 0" />
      <geometry>
        <mesh
          filename="package://medibot4/meshes/right_wheel.STL" />
      </geometry>
      <material
        name="">
        <color
          rgba="0.79216 0.81961 0.93333 1" />
      </material>
    </visual>
    <collision>
      <origin
        xyz="0 0 0"
        rpy="0 0 0" />
      <geometry>
        <mesh
          filename="package://medibot4/meshes/right_wheel.STL" />
      </geometry>
    </collision>
  </link>
  <joint
    name="right_wheel_joint"
    type="continuous">
    <origin
      xyz="-0.189 0.18156 -0.069152"
      rpy="-1.5708 0 -1.5708" />
    <parent
      link="base_link" />
    <child
      link="right_wheel" />
    <axis
      xyz="0 0 1" />
  </joint>
  <link
    name="left_wheel">
    <inertial>
      <origin
        xyz="-2.7756E-17 0 0.1"
        rpy="0 0 0" />
      <mass
        value="18.237" />
      <inertia
        ixx="0.20771"
        ixy="-3.3177E-35"
        ixz="-6.9791E-18"
        iyy="0.20771"
        iyz="-6.8474E-34"
        izz="0.29384" />
    </inertial>
    <visual>
      <origin
        xyz="0 0 0"
        rpy="0 0 0" />
      <geometry>
        <mesh
          filename="package://medibot4/meshes/left_wheel.STL" />
      </geometry>
      <material
        name="">
        <color
          rgba="0.79216 0.81961 0.93333 1" />
      </material>
    </visual>
    <collision>
      <origin
        xyz="0 0 0"
        rpy="0 0 0" />
      <geometry>
        <mesh
          filename="package://medibot4/meshes/left_wheel.STL" />
      </geometry>
    </collision>
  </link>
  <joint
    name="left_wheel_joint"
    type="continuous">
    <origin
      xyz="0.189 0.17969 -0.064239"
      rpy="1.5708 0 1.5708" />
    <parent
      link="base_link" />
    <child
      link="left_wheel" />
    <axis
      xyz="0 0 1" />
  </joint>
</robot>